[2022-02-06 17:39:57,218] {taskinstance.py:1032} INFO - Dependencies all met for <TaskInstance: yellow_taxi_data_ingestion_gcs_dag.download_dataset_task scheduled__2020-02-01T00:00:00+00:00 [queued]>
[2022-02-06 17:39:57,263] {taskinstance.py:1032} INFO - Dependencies all met for <TaskInstance: yellow_taxi_data_ingestion_gcs_dag.download_dataset_task scheduled__2020-02-01T00:00:00+00:00 [queued]>
[2022-02-06 17:39:57,265] {taskinstance.py:1238} INFO - 
--------------------------------------------------------------------------------
[2022-02-06 17:39:57,267] {taskinstance.py:1239} INFO - Starting attempt 1 of 1
[2022-02-06 17:39:57,268] {taskinstance.py:1240} INFO - 
--------------------------------------------------------------------------------
[2022-02-06 17:39:57,321] {taskinstance.py:1259} INFO - Executing <Task(BashOperator): download_dataset_task> on 2020-02-01 00:00:00+00:00
[2022-02-06 17:39:57,333] {standard_task_runner.py:52} INFO - Started process 1094 to run task
[2022-02-06 17:39:57,341] {standard_task_runner.py:76} INFO - Running: ['***', 'tasks', 'run', 'yellow_taxi_data_ingestion_gcs_dag', 'download_dataset_task', 'scheduled__2020-02-01T00:00:00+00:00', '--job-id', '171', '--raw', '--subdir', 'DAGS_FOLDER/yellow_taxi_data_ingestion_gcs_dag.py', '--cfg-path', '/tmp/tmpeobfm5to', '--error-file', '/tmp/tmp9hd4nms0']
[2022-02-06 17:39:57,344] {standard_task_runner.py:77} INFO - Job 171: Subtask download_dataset_task
[2022-02-06 17:39:57,468] {logging_mixin.py:109} INFO - Running <TaskInstance: yellow_taxi_data_ingestion_gcs_dag.download_dataset_task scheduled__2020-02-01T00:00:00+00:00 [running]> on host 4c7ee98729cc
[2022-02-06 17:39:57,636] {logging_mixin.py:109} WARNING - /home/***/.local/lib/python3.7/site-packages/***/utils/context.py:152 AirflowContextDeprecationWarning: Accessing 'execution_date' from the template is deprecated and will be removed in a future version. Please use 'data_interval_start' or 'logical_date' instead.
[2022-02-06 17:39:57,693] {taskinstance.py:1426} INFO - Exporting the following env vars:
AIRFLOW_CTX_DAG_OWNER=***
AIRFLOW_CTX_DAG_ID=yellow_taxi_data_ingestion_gcs_dag
AIRFLOW_CTX_TASK_ID=download_dataset_task
AIRFLOW_CTX_EXECUTION_DATE=2020-02-01T00:00:00+00:00
AIRFLOW_CTX_DAG_RUN_ID=scheduled__2020-02-01T00:00:00+00:00
[2022-02-06 17:39:57,700] {subprocess.py:62} INFO - Tmp dir root location: 
 /tmp
[2022-02-06 17:39:57,704] {subprocess.py:74} INFO - Running command: ['bash', '-c', 'curl -sS https://s3.amazonaws.com/nyc-tlc/trip+data/yellow_tripdata_2020-02.csv > /opt/***/yellow_tripdata_2020-02.csv']
[2022-02-06 17:39:57,730] {subprocess.py:85} INFO - Output:
[2022-02-06 18:07:26,213] {local_task_job.py:212} WARNING - State of this instance has been externally set to restarting. Terminating instance.
[2022-02-06 18:07:26,229] {process_utils.py:124} INFO - Sending Signals.SIGTERM to group 1094. PIDs of all processes in the group: [1096, 1099, 1094]
[2022-02-06 18:07:26,232] {process_utils.py:75} INFO - Sending the signal Signals.SIGTERM to group 1094
[2022-02-06 18:07:26,238] {taskinstance.py:1408} ERROR - Received SIGTERM. Terminating subprocesses.
[2022-02-06 18:07:26,241] {subprocess.py:99} INFO - Sending SIGTERM signal to process group
[2022-02-06 18:07:26,295] {taskinstance.py:1700} ERROR - Task failed with exception
Traceback (most recent call last):
  File "/home/airflow/.local/lib/python3.7/site-packages/airflow/models/taskinstance.py", line 1329, in _run_raw_task
    self._execute_task_with_callbacks(context)
  File "/home/airflow/.local/lib/python3.7/site-packages/airflow/models/taskinstance.py", line 1455, in _execute_task_with_callbacks
    result = self._execute_task(context, self.task)
  File "/home/airflow/.local/lib/python3.7/site-packages/airflow/models/taskinstance.py", line 1511, in _execute_task
    result = execute_callable(context=context)
  File "/home/airflow/.local/lib/python3.7/site-packages/airflow/operators/bash.py", line 182, in execute
    cwd=self.cwd,
  File "/home/airflow/.local/lib/python3.7/site-packages/airflow/hooks/subprocess.py", line 87, in run_command
    for raw_line in iter(self.sub_process.stdout.readline, b''):
  File "/home/airflow/.local/lib/python3.7/site-packages/airflow/models/taskinstance.py", line 1410, in signal_handler
    raise AirflowException("Task received SIGTERM signal")
airflow.exceptions.AirflowException: Task received SIGTERM signal
[2022-02-06 18:07:26,331] {taskinstance.py:1277} INFO - Marking task as UP_FOR_RETRY. dag_id=yellow_taxi_data_ingestion_gcs_dag, task_id=download_dataset_task, execution_date=20200201T000000, start_date=20220206T173957, end_date=20220206T180726
[2022-02-06 18:07:26,390] {standard_task_runner.py:92} ERROR - Failed to execute job 171 for task download_dataset_task
Traceback (most recent call last):
  File "/home/airflow/.local/lib/python3.7/site-packages/airflow/task/task_runner/standard_task_runner.py", line 85, in _start_by_fork
    args.func(args, dag=self.dag)
  File "/home/airflow/.local/lib/python3.7/site-packages/airflow/cli/cli_parser.py", line 48, in command
    return func(*args, **kwargs)
  File "/home/airflow/.local/lib/python3.7/site-packages/airflow/utils/cli.py", line 92, in wrapper
    return f(*args, **kwargs)
  File "/home/airflow/.local/lib/python3.7/site-packages/airflow/cli/commands/task_command.py", line 298, in task_run
    _run_task_by_selected_method(args, dag, ti)
  File "/home/airflow/.local/lib/python3.7/site-packages/airflow/cli/commands/task_command.py", line 107, in _run_task_by_selected_method
    _run_raw_task(args, ti)
  File "/home/airflow/.local/lib/python3.7/site-packages/airflow/cli/commands/task_command.py", line 184, in _run_raw_task
    error_file=args.error_file,
  File "/home/airflow/.local/lib/python3.7/site-packages/airflow/utils/session.py", line 70, in wrapper
    return func(*args, session=session, **kwargs)
  File "/home/airflow/.local/lib/python3.7/site-packages/airflow/models/taskinstance.py", line 1329, in _run_raw_task
    self._execute_task_with_callbacks(context)
  File "/home/airflow/.local/lib/python3.7/site-packages/airflow/models/taskinstance.py", line 1455, in _execute_task_with_callbacks
    result = self._execute_task(context, self.task)
  File "/home/airflow/.local/lib/python3.7/site-packages/airflow/models/taskinstance.py", line 1511, in _execute_task
    result = execute_callable(context=context)
  File "/home/airflow/.local/lib/python3.7/site-packages/airflow/operators/bash.py", line 182, in execute
    cwd=self.cwd,
  File "/home/airflow/.local/lib/python3.7/site-packages/airflow/hooks/subprocess.py", line 87, in run_command
    for raw_line in iter(self.sub_process.stdout.readline, b''):
  File "/home/airflow/.local/lib/python3.7/site-packages/airflow/models/taskinstance.py", line 1410, in signal_handler
    raise AirflowException("Task received SIGTERM signal")
airflow.exceptions.AirflowException: Task received SIGTERM signal
[2022-02-06 18:07:26,458] {process_utils.py:70} INFO - Process psutil.Process(pid=1096, status='terminated', started='17:39:57') (1096) terminated with exit code None
[2022-02-06 18:07:26,461] {process_utils.py:70} INFO - Process psutil.Process(pid=1094, status='terminated', exitcode=1, started='17:39:57') (1094) terminated with exit code 1
[2022-02-06 18:07:26,465] {process_utils.py:70} INFO - Process psutil.Process(pid=1099, status='terminated', started='17:39:57') (1099) terminated with exit code None
